Workbook

Sheet point
B1: calculate as a point mass located at 0,0
A17: k | B17: =density!B25 -> 1 | C17: Taylor Sedov
A18: G | B18: =density!B26 -> 1 | C18: gravity
A19: M | B19: =density!B27 -> 50 | C19: mass
A20: D | B20: =density!B28 -> 10 | C20: Earth to coe
A21: R | B21: 1 | C21: Earth to P
A23: Vo | B23: =B17*B20 -> 10 | C23: observer velocity, all x
A24: dt | B24: 1
A25: Ax observer | B25: =-B18*B19/B20 -> -5 | C25: observer acceleration, all x
A28: v* | B28: =L50 -> 1
A30: min | B30: =MIN(AC50:AC915) -> 0.49979195
A31: avg | B31: =AVERAGE(AC50:AC915) -> 1.0651272 | C31: =B31/B28-1 -> 0.065127196
A32: max | B32: =max(AC50:AC915) -> 1.5555556 | C32: =B32/B30-1 -> 2.1124062
A34: > 0 | B34: =COUNTIF(AC:AC,">"&B28) -> 209 | C34: =B34/B36 -> 0.57894737
A35: < 0 | B35: =COUNTIF(AC:AC,"<"&B28) -> 152 | C35: =B35/B36 -> 0.42105263
A36: total | B36: =B34+B35 -> 361 | C36: 360° = 0°
AF37: 2
A49: degrees | B49: radians | C49: px | D49: py | E49: D | F49: V=kD | G49: theta | H49: Vx | I49: Vy | J49: dVx | K49: dVy | L49: recession v* | N49: A | O49: Ax | P49: Ay | Q49: dAx | R49: dAy | S49: dVx* | T49: dVy* | U49: recession v | W49: =$A49 -> degrees | X49: angle v | Y49: angle a | AA49: =$A49 -> degrees | AB49: recession v* | AC49: =U49 -> recession v | AE49: =AA49 -> degrees | AF49: =AC49 -> recession v
A50: 0 | B50: =RADIANS(A50) -> 0 | C50: =B$20+B$21*COS(B50) -> 11 | D50: =B$21*SIN(B50) -> 0 | E50: =(C50*C50+D50*D50)^0.5 -> 11 | F50: =B$17*E50 -> 11 | G50: =ATAN(D50/C50) -> 0 | H50: =F50*COS(G50) -> 11 | I50: =F50*SIN(G50) -> 0 | J50: =H50-B$23 -> 1 | K50: =I50 -> 0 | L50: =SQRT(J50*J50+K50*K50) -> 1 | N50: =-B$18*B$19/E50 -> -4.5454545 | O50: =N50*COS(G50) -> -4.5454545 | P50: =N50*SIN(G50) -> 0 | Q50: =O50-B$25 -> 0.45454545 | R50: =P50 -> 0 | S50: =J50+Q50*B$24 -> 1.4545455 | T50: =R50+K50*B$24 -> 0 | U50: =SQRT(S50*S50+T50*T50) -> 1.4545455 | W50: =$A50 -> 0 | X50: =ATAN2(S50,T50) -> 0 | Y50: =ATAN(P50/O50) -> 0 | AA50: =A50 -> 0 | AB50: =L50 -> 1 | AC50: =U50 -> 1.4545455 | AE50: =AA50 -> 0 | AF50: =10^AC50 / AF$37 -> 14.240179
A51: 1 | B51: =RADIANS(A51) -> 0.017453293 | C51: =B$20+B$21*COS(B51) -> 10.999848 | D51: =B$21*SIN(B51) -> 0.017452406 | E51: =(C51*C51+D51*D51)^0.5 -> 10.999862 | F51: =B$17*E51 -> 10.999862 | G51: =ATAN(D51/C51) -> 0.001586603 | H51: =F51*COS(G51) -> 10.999848 | I51: =F51*SIN(G51) -> 0.017452406 | J51: =H51-B$23 -> 0.9998477 | K51: =I51 -> 0.017452406 | L51: =SQRT(J51*J51+K51*K51) -> 1 | N51: =-B$18*B$19/E51 -> -4.5455118 | O51: =N51*COS(G51) -> -4.545506 | P51: =N51*SIN(G51) -> -0.0072119198 | Q51: =O51-B$25 -> 0.45449396 | R51: =P51 -> -0.0072119198 | S51: =J51+Q51*B$24 -> 1.4543417 | T51: =R51+K51*B$24 -> 0.010240487 | U51: =SQRT(S51*S51+T51*T51) -> 1.4543777 | W51: =$A51 -> 1 | X51: =ATAN2(S51,T51) -> 0.0070412048 | Y51: =ATAN(P51/O51) -> 0.001586603 | AA51: =A51 -> 1 | AB51: =L51 -> 1 | AC51: =U51 -> 1.4543777 | AE51: =AA51 -> 1 | AF51: =10^AC51 / AF$37 -> 14.23468
A52: 2 | B52: =RADIANS(A52) -> 0.034906585 | C52: =B$20+B$21*COS(B52) -> 10.999391 | D52: =B$21*SIN(B52) -> 0.034899497 | E52: =(C52*C52+D52*D52)^0.5 -> 10.999446 | F52: =B$17*E52 -> 10.999446 | G52: =ATAN(D52/C52) -> 0.0031728466 | H52: =F52*COS(G52) -> 10.999391 | I52: =F52*SIN(G52) -> 0.034899497 | J52: =H52-B$23 -> 0.99939083 | K52: =I52 -> 0.034899497 | L52: =SQRT(J52*J52+K52*K52) -> 1 | N52: =-B$18*B$19/E52 -> -4.5456834 | O52: =N52*COS(G52) -> -4.5456605 | P52: =N52*SIN(G52) -> -0.014422732 | Q52: =O52-B$25 -> 0.45433948 | R52: =P52 -> -0.014422732 | S52: =J52+Q52*B$24 -> 1.4537303 | T52: =R52+K52*B$24 -> 0.020476765 | U52: =SQRT(S52*S52+T52*T52) -> 1.4538745 | W52: =$A52 -> 2 | X52: =ATAN2(S52,T52) -> 0.014084738 | Y52: =ATAN(P52/O52) -> 0.0031728466 | AA52: =A52 -> 2 | AB52: =L52 -> 1 | AC52: =U52 -> 1.4538745 | AE52: =AA52 -> 2 | AF52: =10^AC52 / AF$37 -> 14.218197
A53: 3 | B53: =RADIANS(A53) -> 0.052359878 | C53: =B$20+B$21*COS(B53) -> 10.99863 | D53: =B$21*SIN(B53) -> 0.052335956 | E53: =(C53*C53+D53*D53)^0.5 -> 10.998754 | F53: =B$17*E53 -> 10.998754 | G53: =ATAN(D53/C53) -> 0.0047583711 | H53: =F53*COS(G53) -> 10.99863 | I53: =F53*SIN(G53) -> 0.052335956 | J53: =H53-B$23 -> 0.99862953 | K53: =I53 -> 0.052335956 | L53: =SQRT(J53*J53+K53*K53) -> 1 | N53: =-B$18*B$19/E53 -> -4.5459695 | O53: =N53*COS(G53) -> -4.545918 | P53: =N53*SIN(G53) -> -0.021631328 | Q53: =O53-B$25 -> 0.45408201 | R53: =P53 -> -0.021631328 | S53: =J53+Q53*B$24 -> 1.4527115 | T53: =R53+K53*B$24 -> 0.030704628 | U53: =SQRT(S53*S53+T53*T53) -> 1.453036 | W53: =$A53 -> 3 | X53: =ATAN2(S53,T53) -> 0.021132934 | Y53: =ATAN(P53/O53) -> 0.0047583711 | AA53: =A53 -> 3 | AB53: =L53 -> 1 | AC53: =U53 -> 1.453036 | AE53: =AA53 -> 3 | AF53: =10^AC53 / AF$37 -> 14.190771
A54: 4 | B54: =RADIANS(A54) -> 0.06981317 | C54: =B$20+B$21*COS(B54) -> 10.997564 | D54: =B$21*SIN(B54) -> 0.069756474 | E54: =(C54*C54+D54*D54)^0.5 -> 10.997785 | F54: =B$17*E54 -> 10.997785 | G54: =ATAN(D54/C54) -> 0.0063428172 | H54: =F54*COS(G54) -> 10.997564 | I54: =F54*SIN(G54) -> 0.069756474 | J54: =H54-B$23 -> 0.99756405 | K54: =I54 -> 0.069756474 | L54: =SQRT(J54*J54+K54*K54) -> 1 | N54: =-B$18*B$19/E54 -> -4.5463699 | O54: =N54*COS(G54) -> -4.5462785 | P54: =N54*SIN(G54) -> -0.0288366 | Q54: =O54-B$25 -> 0.45372155 | R54: =P54 -> -0.0288366 | S54: =J54+Q54*B$24 -> 1.4512856 | T54: =R54+K54*B$24 -> 0.040919874 | U54: =SQRT(S54*S54+T54*T54) -> 1.4518624 | W54: =$A54 -> 4 | X54: =ATAN2(S54,T54) -> 0.028188136 | Y54: =ATAN(P54/O54) -> 0.0063428172 | AA54: =A54 -> 4 | AB54: =L54 -> 1 | AC54: =U54 -> 1.4518624 | AE54: =AA54 -> 4 | AF54: =10^AC54 / AF$37 -> 14.152474
A55: 5 | B55: =RADIANS(A55) -> 0.087266463 | C55: =B$20+B$21*COS(B55) -> 10.996195 | D55: =B$21*SIN(B55) -> 0.087155743 | E55: =(C55*C55+D55*D55)^0.5 -> 10.99654 | F55: =B$17*E55 -> 10.99654 | G55: =ATAN(D55/C55) -> 0.0079258253 | H55: =F55*COS(G55) -> 10.996195 | I55: =F55*SIN(G55) -> 0.087155743 | J55: =H55-B$23 -> 0.9961947 | K55: =I55 -> 0.087155743 | L55: =SQRT(J55*J55+K55*K55) -> 1 | N55: =-B$18*B$19/E55 -> -4.5468847 | O55: =N55*COS(G55) -> -4.5467419 | P55: =N55*SIN(G55) -> -0.036037436 | Q55: =O55-B$25 -> 0.4532581 | R55: =P55 -> -0.036037436 | S55: =J55+Q55*B$24 -> 1.4494528 | T55: =R55+K55*B$24 -> 0.051118306 | U55: =SQRT(S55*S55+T55*T55) -> 1.4503539 | W55: =$A55 -> 5 | X55: =ATAN2(S55,T55) -> 0.035252703 | Y55: =ATAN(P55/O55) -> 0.0079258253 | AA55: =A55 -> 5 | AB55: =L55 -> 1 | AC55: =U55 -> 1.4503539 | AE55: =AA55 -> 5 | AF55: =10^AC55 / AF$37 -> 14.103403
A56: 6 | B56: =RADIANS(A56) -> 0.10471976 | C56: =B$20+B$21*COS(B56) -> 10.994522 | D56: =B$21*SIN(B56) -> 0.10452846 | E56: =(C56*C56+D56*D56)^0.5 -> 10.995019 | F56: =B$17*E56 -> 10.995019 | G56: =ATAN(D56/C56) -> 0.0095070359 | H56: =F56*COS(G56) -> 10.994522 | I56: =F56*SIN(G56) -> 0.10452846 | J56: =H56-B$23 -> 0.9945219 | K56: =I56 -> 0.10452846 | L56: =SQRT(J56*J56+K56*K56) -> 1 | N56: =-B$18*B$19/E56 -> -4.5475138 | O56: =N56*COS(G56) -> -4.5473083 | P56: =N56*SIN(G56) -> -0.043232726 | Q56: =O56-B$25 -> 0.45269167 | R56: =P56 -> -0.043232726 | S56: =J56+Q56*B$24 -> 1.4472136 | T56: =R56+K56*B$24 -> 0.061295737 | U56: =SQRT(S56*S56+T56*T56) -> 1.4485111 | W56: =$A56 -> 6 | X56: =ATAN2(S56,T56) -> 0.042329015 | Y56: =ATAN(P56/O56) -> 0.0095070359 | AA56: =A56 -> 6 | AB56: =L56 -> 1 | AC56: =U56 -> 1.4485111 | AE56: =AA56 -> 6 | AF56: =10^AC56 / AF$37 -> 14.043684
A57: 7 | B57: =RADIANS(A57) -> 0.12217305 | C57: =B$20+B$21*COS(B57) -> 10.992546 | D57: =B$21*SIN(B57) -> 0.12186934 | E57: =(C57*C57+D57*D57)^0.5 -> 10.993222 | F57: =B$17*E57 -> 10.993222 | G57: =ATAN(D57/C57) -> 0.01108609 | H57: =F57*COS(G57) -> 10.992546 | I57: =F57*SIN(G57) -> 0.12186934 | J57: =H57-B$23 -> 0.99254615 | K57: =I57 -> 0.12186934 | L57: =SQRT(J57*J57+K57*K57) -> 1 | N57: =-B$18*B$19/E57 -> -4.5482572 | O57: =N57*COS(G57) -> -4.5479777 | P57: =N57*SIN(G57) -> -0.050421354 | Q57: =O57-B$25 -> 0.45202226 | R57: =P57 -> -0.050421354 | S57: =J57+Q57*B$24 -> 1.4445684 | T57: =R57+K57*B$24 -> 0.071447989 | U57: =SQRT(S57*S57+T57*T57) -> 1.4463342 | W57: =$A57 -> 7 | X57: =ATAN2(S57,T57) -> 0.049419476 | Y57: =ATAN(P57/O57) -> 0.01108609 | AA57: =A57 -> 7 | AB57: =L57 -> 1 | AC57: =U57 -> 1.4463342 | AE57: =AA57 -> 7 | AF57: =10^AC57 / AF$37 -> 13.973469
A58: 8 | B58: =RADIANS(A58) -> 0.13962634 | C58: =B$20+B$21*COS(B58) -> 10.990268 | D58: =B$21*SIN(B58) -> 0.1391731 | E58: =(C58*C58+D58*D58)^0.5 -> 10.991149 | F58: =B$17*E58 -> 10.991149 | G58: =ATAN(D58/C58) -> 0.012662627 | H58: =F58*COS(G58) -> 10.990268 | I58: =F58*SIN(G58) -> 0.1391731 | J58: =H58-B$23 -> 0.99026807 | K58: =I58 -> 0.1391731 | L58: =SQRT(J58*J58+K58*K58) -> 1 | N58: =-B$18*B$19/E58 -> -4.5491148 | O58: =N58*COS(G58) -> -4.5487501 | P58: =N58*SIN(G58) -> -0.057602204 | Q58: =O58-B$25 -> 0.45124987 | R58: =P58 -> -0.057602204 | S58: =J58+Q58*B$24 -> 1.4415179 | T58: =R58+K58*B$24 -> 0.081570897 | U58: =SQRT(S58*S58+T58*T58) -> 1.443824 | W58: =$A58 -> 8 | X58: =ATAN2(S58,T58) -> 0.056526524 | Y58: =ATAN(P58/O58) -> 0.012662627 | AA58: =A58 -> 8 | AB58: =L58 -> 1 | AC58: =U58 -> 1.443824 | AE58: =AA58 -> 8 | AF58: =10^AC58 / AF$37 -> 13.892935
A59: 9 | B59: =RADIANS(A59) -> 0.15707963 | C59: =B$20+B$21*COS(B59) -> 10.987688 | D59: =B$21*SIN(B59) -> 0.15643446 | E59: =(C59*C59+D59*D59)^0.5 -> 10.988802 | F59: =B$17*E59 -> 10.988802 | G59: =ATAN(D59/C59) -> 0.014236288 | H59: =F59*COS(G59) -> 10.987688 | I59: =F59*SIN(G59) -> 0.15643446 | J59: =H59-B$23 -> 0.98768834 | K59: =I59 -> 0.15643446 | L59: =SQRT(J59*J59+K59*K59) -> 1 | N59: =-B$18*B$19/E59 -> -4.5500866 | O59: =N59*COS(G59) -> -4.5496255 | P59: =N59*SIN(G59) -> -0.064774155 | Q59: =O59-B$25 -> 0.4503745 | R59: =P59 -> -0.064774155 | S59: =J59+Q59*B$24 -> 1.4380628 | T59: =R59+K59*B$24 -> 0.09166031 | U59: =SQRT(S59*S59+T59*T59) -> 1.440981 | W59: =$A59 -> 9 | X59: =ATAN2(S59,T59) -> 0.063652632 | Y59: =ATAN(P59/O59) -> 0.014236288 | AA59: =A59 -> 9 | AB59: =L59 -> 1 | AC59: =U59 -> 1.440981 | AE59: =AA59 -> 9 | AF59: =10^AC59 / AF$37 -> 13.802286
A60: 10 | B60: =RADIANS(A60) -> 0.17453293 | C60: =B$20+B$21*COS(B60) -> 10.984808 | D60: =B$21*SIN(B60) -> 0.17364818 | E60: =(C60*C60+D60*D60)^0.5 -> 10.98618 | F60: =B$17*E60 -> 10.98618 | G60: =ATAN(D60/C60) -> 0.015806714 | H60: =F60*COS(G60) -> 10.984808 | I60: =F60*SIN(G60) -> 0.17364818 | J60: =H60-B$23 -> 0.98480775 | K60: =I60 -> 0.17364818 | L60: =SQRT(J60*J60+K60*K60) -> 1 | N60: =-B$18*B$19/E60 -> -4.5511724 | O60: =N60*COS(G60) -> -4.5506038 | P60: =N60*SIN(G60) -> -0.071936085 | Q60: =O60-B$25 -> 0.44939615 | R60: =P60 -> -0.071936085 | S60: =J60+Q60*B$24 -> 1.4342039 | T60: =R60+K60*B$24 -> 0.10171209 | U60: =SQRT(S60*S60+T60*T60) -> 1.437806 | W60: =$A60 -> 10 | X60: =ATAN2(S60,T60) -> 0.070800313 | Y60: =ATAN(P60/O60) -> 0.015806714 | AA60: =A60 -> 10 | AB60: =L60 -> 1 | AC60: =U60 -> 1.437806 | AE60: =AA60 -> 10 | AF60: =10^AC60 / AF$37 -> 13.70175
A61: 11 | B61: =RADIANS(A61) -> 0.19198622 | C61: =B$20+B$21*COS(B61) -> 10.981627 | D61: =B$21*SIN(B61) -> 0.190809 | E61: =(C61*C61+D61*D61)^0.5 -> 10.983285 | F61: =B$17*E61 -> 10.983285 | G61: =ATAN(D61/C61) -> 0.017373545 | H61: =F61*COS(G61) -> 10.981627 | I61: =F61*SIN(G61) -> 0.190809 | J61: =H61-B$23 -> 0.98162718 | K61: =I61 -> 0.190809 | L61: =SQRT(J61*J61+K61*K61) -> 1 | N61: =-B$18*B$19/E61 -> -4.5523722 | O61: =N61*COS(G61) -> -4.5516852 | P61: =N61*SIN(G61) -> -0.079086866 | Q61: =O61-B$25 -> 0.44831484 | R61: =P61 -> -0.079086866 | S61: =J61+Q61*B$24 -> 1.429942 | T61: =R61+K61*B$24 -> 0.11172213 | U61: =SQRT(S61*S61+T61*T61) -> 1.4342998 | W61: =$A61 -> 11 | X61: =ATAN2(S61,T61) -> 0.077972132 | Y61: =ATAN(P61/O61) -> 0.017373545 | AA61: =A61 -> 11 | AB61: =L61 -> 1 | AC61: =U61 -> 1.4342998 | AE61: =AA61 -> 11 | AF61: =10^AC61 / AF$37 -> 13.591577
... A410: 360 | B410: =RADIANS(A410) -> 6.2831853 | C410: =B$20+B$21*COS(B410) -> 11 | D410: =B$21*SIN(B410) -> 0 | E410: =(C410*C410+D410*D410)^0.5 -> 11 | F410: =B$17*E410 -> 11 | G410: =ATAN(D410/C410) -> 0 | H410: =F410*COS(G410) -> 11 | I410: =F410*SIN(G410) -> 0 | J410: =H410-B$23 -> 1 | K410: =I410 -> 0 | L410: =SQRT(J410*J410+K410*K410) -> 1 | N410: =-B$18*B$19/E410 -> -4.5454545 | O410: =N410*COS(G410) -> -4.5454545 | P410: =N410*SIN(G410) -> 0 | Q410: =O410-B$25 -> 0.45454545 | R410: =P410 -> 0 | S410: =J410+Q410*B$24 -> 1.4545455 | T410: =R410+K410*B$24 -> 0 | U410: =SQRT(S410*S410+T410*T410) -> 1.4545455 | W410: =$A410 -> 360 | X410: =ATAN2(S410,T410) -> 0 | Y410: =ATAN(P410/O410) -> 0 | AA410: =A410 -> 360 | AB410: =L410 -> 1 | AC410: =U410 -> 1.4545455 | AE410: =AA410 -> 360 | AF410: =10^AC410 / AF$37 -> 14.240179

Sheet density
C3: model as distributed density
B12: 0.5
B14: 2
B15: 1
B16: 10
B17: 2
B18: 0.5
A21: m(R)/M = 1 - exp(-X)*(1+X+{X^{2}/2})
A22: x=R/L
A23: L | B23: 0.5
A25: k | B25: 1 | C25: Taylor Sedov
A26: G | B26: 1 | C26: gravity
A27: M | B27: 50 | C27: mass
A28: D | B28: 10 | C28: Earth to coe
A29: R | B29: 2 | C29: Earth to P
A32: Vo | B32: =B25*B28 -> 10 | C32: observer velocity, all x
A33: dt | B33: 1
A34: Ax observer | B34: =-B26*B27/(B28*B28) -> -0.5 | C34: observer acceleration, all x
A36: v* | B36: =B29*B25 -> 2
A37: normalized v* | B37: 1
A39: min | B39: =MIN(AF46:AF1112) -> 0.066688232
A40: avg | B40: =AVERAGE(AF66:AF1001) -> 1.0135336 | C40: =B40-1 -> 0.013533616
A41: max | B41: =max(AF65:AF1112) -> 1.0899972 | C41: =B41/B39-1 -> 15.344671
A43: > v* | B43: =COUNTIF(AF:AF,">"&B37) -> 208 | C43: =B43/B45 -> 0.56830601
A44: < v* | B44: =COUNTIF(AF:AF,"<"&B37) -> 158 | C44: =B44/B45 -> 0.43169399
A45: total | B45: =B43+B44 -> 366 | C45: 360° = 0°
AK46: 2
A48: 0° | B48: =AF66 -> 1.0639567 | C48: =B50/B48-1 -> 0.024475199
A49: ~90° | B49: =MIN(AF:AF) -> 0.066688232 | C49: =B50/B49-1 -> 15.344671 | AF49: {=LINEST(AG68:AG426,AF68:AF426,1,1)} -> 0.82846881 | AG49: 0.19386087
A50: 180° | B50: =AF246 -> 1.0899972 | AF50: 0.066688232 | AG50: 0.067638308
AF51: 0.30182247 | AG51: 0.056717431
A52: angle of minimum | B52: =VLOOKUP(B49,AF66:AJ1112,3,0) -> #N/A | C52: =180-(B52-180) -> #N/A | AF52: 154.33127 | AG52: 357
C53: =abs(C52-B52) -> #N/A | AF53: 0.49646316 | AG53: 1.1484215
A54: avg density to o | B54: =B27/((B28)^B53 * PI() * 4/3) -> 11.936621
A55: fraction up to o | B55: =(1-exp(-B28/C61)*(1+ B28/C61 + B28*B28/C61/C61/2)) -> 0.87534798 | AT55: =MAX(E66:E931) -> 12
A56: total mass | B56: =B27/B55 -> 57.120141
A57: check | B57: =B56*B55 -> 50
B59: m(R)/M = 1 - exp(-X)*(1+X+{X^{2}/2})
B60: x=R/L
B61: L | C61: 2 | AH61: =AH63/AG63 -> 0.046788727
...

Sheet density error fx
C3: angular error calculated
B12: 0.5
B14: 2
B15: 1
B16: 10
B17: 2
B18: 0.5
A21: m(R)/M = 1 - exp(-X)*(1+X+{X^{2}/2}) | E21: =AH61 -> 0.039269198
A22: x=R/L
A23: L | B23: 0.5
A25: k | B25: 1 | C25: Taylor Sedov
A26: G | B26: 1.8 | C26: gravity
A27: M | B27: 50 | C27: mass
A28: D | B28: 12 | C28: Earth to coe
A29: R | B29: 4 | C29: Earth to P
A32: Vo | B32: =B25*B28 -> 12 | C32: observer velocity, all x
A33: dt | B33: 1 | E33: =AP61 -> 0.053434554
A34: Ax observer | B34: =-B26*B27/(B28*B28) -> -0.625 | C34: observer acceleration, all x
A36: v* | B36: =B29*B25 -> 4
A37: normalized v* | B37: 1
A39: min | B39: =MIN(AF66:AF1112) -> 0.9469509
A40: avg | B40: =AVERAGE(AF66:AF1001) -> 1.0190552 | C40: =B40-1 -> 0.019055181
A41: max | B41: =max(AF65:AF1112) -> 1.1292995 | C41: =B41/B39-1 -> 0.19256391
A43: > v* | B43: =COUNTIF(AF:AF,">"&B37) -> 212 | C43: =B43/B45 -> 0.57923497
A44: < v* | B44: =COUNTIF(AF:AF,"<"&B37) -> 154 | C44: =B44/B45 -> 0.42076503
A45: total | B45: =B43+B44 -> 366 | C45: 360° = 0°
AK46: 2
A48: 0° | B48: =AF66 -> 1.0638418 | C48: =B50/B48-1 -> 0.061529517
A49: ~90° | B49: =MIN(AF66:AF931) -> 0.9469509 | C49: =B50/B49-1 -> 0.19256391 | AF49: {=LINEST(AG68:AG426,AF68:AF426,1,1)} -> 0.91942337 | AG49: 0.091943583 | AM49: {=LINEST(AN68:AN426,AM68:AM426,1,1)} -> 0.87030131 | AN49: 0.12242306
A50: 180° | B50: =AF246 -> 1.1292995 | AF50: 0.049678428 | AG50: 0.050681587 | AM50: 0.059071937 | AN50: 0.058037507
AF51: 0.48965549 | AG51: 0.050062663 | AM51: 0.37811219 | AN51: 0.064020144
A52: angle of minimum | B52: =VLOOKUP(B49,AF66:AJ1112,3,0) -> 0.053049098 | C52: =180-(B52-180) -> 359.94695 | AF52: 342.52746 | AG52: 357 | AM52: 217.05853 | AN52: 357
C53: =abs(C52-B52) -> 359.8939 | AF53: 0.85846638 | AG53: 0.89473847 | AM53: 0.88963149 | AN53: 1.4631927
A54: avg density to o | B54: =B27/((B28)^B53 * PI() * 4/3) -> 11.936621
A55: fraction up to o | B55: =(1-exp(-B28/C61)*(1+ B28/C61 + B28*B28/C61/C61/2)) -> 0.9380312 | AM55: 0.1 | AV55: =MAX(E66:E931) -> 16
A56: total mass | B56: =B27/B55 -> 53.303131
A57: check | B57: =B56*B55 -> 50 | BA57: -0.09 | BE57: =-BA57 -> 0.09
BA58: =BB58 -> 0.017453293 | BB58: =2*pi()/360 -> 0.017453293 | BE58: =BA58 -> 0.017453293
B59: m(R)/M = 1 - exp(-X)*(1+X+{X^{2}/2}) | BA59: 0.25 | BE59: =BA59 -> 0.25
B60: x=R/L
...

Sheet density w rotation
C2: distributed mass density with added error ie rotation?
C3: R2w/R2wo a | D3: =BH58/AF51 -> 1.4535821
C4: R2w/R2wo b | D4: =BL58/AM51 -> 1.9288175
A7: c | B7: 100
A8: v/c | B8: =B32/B7 -> 0.1
A9: squared | B9: =B8*B8 -> 0.01
B10: =SQRT(1-B9) -> 0.99498744
B12: 0.5
B14: 2
B15: 1
B16: 10
B17: 2
B18: 0.5
A21: m(R)/M = 1 - exp(-X)*(1+X+{X^{2}/2}) | E21: =AH61 -> 0.039938592
A22: x=R/L
A23: L | B23: 0.5
AO24: =64/48 -> 1.3333333
A25: k | B25: 1 | C25: Taylor Sedov
A26: G | B26: 1 | C26: gravity
A27: M | B27: 50 | C27: mass
A28: D | B28: 10 | C28: Earth to coe
A29: R | B29: 3 | C29: Earth to P
A30: L | B30: 1.5 | C30: density distribution
A32: Vo | B32: =B25*B28 -> 10 | C32: observer velocity, all x
A33: dt | B33: 1 | E33: =AP61 -> 0.041269454
A34: Ax observer | B34: =-B26*B27/(B28*B28) -> -0.5 | C34: observer acceleration, all x
A36: v* | B36: =B29*B25 -> 3
A37: normalized v* | B37: 1
A39: min | B39: =MIN(AF66:AF1112) -> 0.9492305 | E39: 0.09
A40: avg | B40: =AVERAGE(AF66:AF1001) -> 1.0213092 | C40: =B40-1 -> 0.021309243
A41: max | B41: =max(AF65:AF1112) -> 1.1318723 | C41: =B41/B39-1 -> 0.19241039
A43: > v* | B43: =COUNTIF(AF:AF,">"&B37) -> 216 | C43: =B43/B45 -> 0.59016393
A44: < v* | B44: =COUNTIF(AF:AF,"<"&B37) -> 150 | C44: =B44/B45 -> 0.40983607
A45: total | B45: =B43+B44 -> 366 | C45: 360° = 0°
AK46: 2
A48: 0° | B48: =AF66 -> 1.0649816 | C48: =B50/B48-1 -> 0.062809292
A49: ~90° | B49: =MIN(AF66:AF931) -> 0.9492305 | C49: =B50/B49-1 -> 0.19241039 | AF49: {=LINEST(AG68:AG426,AF68:AF426,1,1)} -> 0.89863109 | AG49: 0.11109573 | AM49: {=LINEST(AN68:AN426,AM68:AM426,1,1)} -> 0.55795816 | AN49: 0.4303492
A50: 180° | B50: =AF246 -> 1.1318723 | AF50: 0.05028627 | AG50: 0.051415865 | AM50: 0.037883786 | AN50: 0.037598591
AF51: 0.47216513 | AG51: 0.050913302 | AM51: 0.37796042 | AN51: 0.041057151
A52: angle of minimum | B52: =VLOOKUP(B49,AF66:AJ1112,5,0) -> 103 | C52: =180-(B52-180) -> 257 | AF52: 319.34788 | AG52: 357 | AM52: 216.91846 | AN52: 357
...

Sheet Copy of density w rotation
C2: distributed mass density with added error ie rotation?
C3: R2w/R2wo a | D3: =BH58/AF51 -> 1.1847453
C4: R2w/R2wo b | D4: =BL58/AM51 -> 1.9564294
A7: c | B7: 100
A8: v/c | B8: =B32/B7 -> 2.772e+30
A9: squared | B9: =B8*B8 -> 7.68398e+60
B10: =SQRT(1-B9) -> #NUM!
B12: 0.5
B14: 2
B15: 1
B16: 10
B17: 2
B18: 0.5
A21: m(R)/M = 1 - exp(-X)*(1+X+{X^{2}/2}) | E21: =AH61 -> 0.042179643
A22: x=R/L
A23: L | B23: 0.5 | C23: 9 | D23: 0.25
AO24: =64/48 -> 1.3333333
A25: k | B25: 70000 | C25: Taylor Sedov
A26: G | B26: 6.67e-11 | C26: gravity
A27: M | B27: 3e+96 | C27: mass | D27: =B27/1E+52 -> 3e+44
A28: D | B28: =B29*C23 -> 3.96e+27 | C28: Earth to coe | E28: =D27/D29 -> 4.11523e+41
A29: R | B29: 4.4e+26 | C29: Earth to P | D29: =(B28/B29)^3 -> 729
A30: L | B30: =B28*D23 -> 9.9e+26 | C30: density distribution
A32: Vo | B32: =B25*B28 -> 2.772e+32 | C32: observer velocity, all x
A33: dt | B33: 1 | E33: =AP61 -> 0.0432502
A34: Ax observer | B34: =-B26*B27/(B28*B28) -> -1.27602e+31 | C34: observer acceleration, all x
A36: v* | B36: =B29*B25 -> 3.08e+31
A37: normalized v* | B37: 1
A39: min | B39: =MIN(AF66:AF1112) -> 0.95389493 | E39: 0.09
A40: avg | B40: =AVERAGE(AF66:AF1001) -> 1.0058989 | C40: =B40-1 -> 0.0058989036
A41: max | B41: =max(AF65:AF1112) -> 1.0600893 | C41: =B41/B39-1 -> 0.1113271
A43: > v* | B43: =COUNTIF(AF:AF,">"&B37) -> 197 | C43: =B43/B45 -> 0.53825137
A44: < v* | B44: =COUNTIF(AF:AF,"<"&B37) -> 169 | C44: =B44/B45 -> 0.46174863
A45: total | B45: =B43+B44 -> 366 | C45: 360° = 0°
AK46: 2
A48: 0° | B48: =AF66 -> 1.0530904 | C48: =B50/B48-1 -> 0.0066460506
A49: ~90° | B49: =MIN(AF66:AF931) -> 0.95389493 | C49: =B50/B49-1 -> 0.1113271 | AF49: {=LINEST(AG68:AG426,AF68:AF426,1,1)} -> 1.3657914 | AG49: -0.34483172 | AM49: {=LINEST(AN68:AN426,AM68:AM426,1,1)} -> 0.62912608 | AN49: 0.37408194
A50: 180° | B50: =AF246 -> 1.0600893 | AF50: 0.072138517 | AG50: 0.072592125 | AM50: 0.044992446 | AN50: 0.044653736
AF51: 0.50101666 | AG51: 0.049502285 | AM51: 0.35387217 | AN51: 0.048761273
A52: angle of minimum | B52: =VLOOKUP(B49,AF66:AJ1112,5,0) -> 95 | C52: =180-(B52-180) -> 265 | AF52: 358.45475 | AG52: 357 | AM52: 195.52225 | AN52: 357
...

Sheet Copy of Copy of density w rotat
C2: distributed mass density with added error ie rotation?
C3: R2w/R2wo a | D3: =BH58/AF51 -> 1.483706
C4: R2w/R2wo b | D4: =BL58/AM51 -> 2.0032665
A7: c | B7: 100
A8: v/c | B8: =B32/B7 -> 56277419
A9: squared | B9: =B8*B8 -> 3.16715e+15
B10: =SQRT(1-B9) -> #NUM!
B12: 0.5
B14: 2
B15: 1
B16: 10
B17: 2
B18: 0.5
A21: m(R)/M = 1 - exp(-X)*(1+X+{X^{2}/2}) | E21: =AH61 -> 0.037247309
A22: x=R/L
A23: L | B23: 0.5 | C23: 6.1 | D23: 0.199
AO24: =64/48 -> 1.3333333
A25: k | B25: =65000/(3.1E+22) -> 0 | C25: Taylor Sedov Hubble constant
A26: G | B26: 6.67e-11 | C26: gravity
A27: M | B27: =D27*E27 -> 3.3e+73 | C27: mass | D27: =(10^54) -> 1e+54 | E27: 3.3e+19
A28: D | B28: =B29*C23 -> 2.684e+27 | C28: Earth to coe | E28: =D27/D29 -> 4.40566e+51
A29: R | B29: 4.4e+26 | C29: Earth to P | D29: =(B28/B29)^3 -> 226.981
A30: L | B30: =B28*D23 -> 5.34116e+26 | C30: density distribution
A32: Vo | B32: =B25*B28 -> 5627741935 | C32: observer velocity, all x
A33: dt | B33: 1 | E33: =AP61 -> 0.040947711
A34: Ax observer | B34: =-B26*B27/(B28*B28) -> -3.055447e+08 | C34: observer acceleration, all x
A36: v* | B36: =B29*B25 -> 9.2258065e+08
A37: normalized v* | B37: 1
A39: min | B39: =MIN(AF66:AF1112) -> 0.94549024 | E39: 0.09
A40: avg | B40: =AVERAGE(AF66:AF1001) -> 1.01517 | C40: =B40-1 -> 0.015170019
A41: max | B41: =max(AF65:AF1112) -> 1.0953569 | C41: =B41/B39-1 -> 0.15850678
A43: > v* | B43: =COUNTIF(AF:AF,">"&B37) -> 209 | C43: =B43/B45 -> 0.57103825
A44: < v* | B44: =COUNTIF(AF:AF,"<"&B37) -> 157 | C44: =B44/B45 -> 0.42896175
A45: total | B45: =B43+B44 -> 366 | C45: 360° = 0°
AK46: 2
A48: 0° | B48: =AF66 -> 1.0718183 | C48: =B50/B48-1 -> 0.021961291
A49: ~90° | B49: =MIN(AF66:AF931) -> 0.94549024 | C49: =B50/B49-1 -> 0.15850678 | AF49: {=LINEST(AG68:AG426,AF68:AF426,1,1)} -> 1.0164089 | AG49: -0.0028498144 | AM49: {=LINEST(AN68:AN426,AM68:AM426,1,1)} -> 0.5945459 | AN49: 0.40432919
A50: 180° | B50: =AF246 -> 1.0953569 | AF50: 0.053537489 | AG50: 0.054395368 | AM50: 0.041561616 | AN50: 0.041248734
AF51: 0.5023905 | AG51: 0.049434092 | AM51: 0.36435906 | AN51: 0.045043058
A52: angle of minimum | B52: =VLOOKUP(B49,AF66:AJ1112,5,0) -> 97 | C52: =180-(B52-180) -> 263 | AF52: 360.43003 | AG52: 357 | AM52: 204.63783 | AN52: 357
...

Sheet Copy of Copy of Copy of density
C2: distributed mass density with added error ie rotation?
C3: R2w/R2wo a | D3: =BH58/AF51 -> 1.4807285
C4: R2w/R2wo b | D4: =BL58/AM51 -> 1.9788852
A7: c | B7: 100
A8: v/c | B8: =B32/B7 -> 14170
A9: squared | B9: =B8*B8 -> 200788900
B10: =SQRT(1-B9) -> #NUM!
B12: 0.5
B14: 2
B15: 1
B16: 10
B17: 2
B18: 0.5
A21: m(R)/M = 1 - exp(-X)*(1+X+{X^{2}/2}) | E21: =AH61 -> 0.037767258
A22: x=R/L
A23: L | B23: 0.5 | C23: 5 | D23: 0.18
AO24: =64/48 -> 1.3333333
A25: k 1/s | B25: 2.18e-18 | C25: Taylor Sedov Hubble constant
A26: G N(km/kg)^2 | B26: 6.67e-17 | C26: gravity
A27: M kg | B27: =D27*E27*10000000000000 -> 4.44e+68 | C27: mass | D27: =(10^53) -> 1e+53 | E27: 444
A28: D km | B28: =B29*C23 -> 6.5e+23 | C28: Earth to coe | E28: =D27/D29 -> 8e+50
A29: R km | B29: 1.3e+23 | C29: Earth to P | D29: =(B28/B29)^3 -> 125
A30: L km | B30: =B28*D23 -> 1.17e+23 | C30: density distribution
A32: Vo | B32: =B25*B28 -> 1417000 | C32: observer velocity, all x
A33: dt | B33: 1 | E33: =AP61 -> 0.04012251
A34: Ax observer | B34: =-B26*B27/(B28*B28) -> -70094.201 | C34: observer acceleration, all x
A36: v* | B36: =B29*B25 -> 283400
A37: normalized v* | B37: 1
A39: min | B39: =MIN(AF66:AF1112) -> 0.95023117 | E39: 0.09
A40: avg | B40: =AVERAGE(AF66:AF1001) -> 1.0165656 | C40: =B40-1 -> 0.016565605
A41: max | B41: =max(AF65:AF1112) -> 1.0990339 | C41: =B41/B39-1 -> 0.15659632
A43: > v* | B43: =COUNTIF(AF:AF,">"&B37) -> 213 | C43: =B43/B45 -> 0.58196721
A44: < v* | B44: =COUNTIF(AF:AF,"<"&B37) -> 153 | C44: =B44/B45 -> 0.41803279
A45: total | B45: =B43+B44 -> 366 | C45: 360° = 0°
AK46: 2
A48: 0° | B48: =AF66 -> 1.066758 | C48: =B50/B48-1 -> 0.030256073
A49: ~90° | B49: =MIN(AF66:AF931) -> 0.95023117 | C49: =B50/B49-1 -> 0.15659632 | AF49: {=LINEST(AG68:AG426,AF68:AF426,1,1)} -> 1.0520913 | AG49: -0.040568337 | AM49: {=LINEST(AN68:AN426,AM68:AM426,1,1)} -> 0.57494359 | AN49: 0.42097218
A50: 180° | B50: =AF246 -> 1.0990339 | AF50: 0.055789886 | AG50: 0.056758883 | AM50: 0.039669001 | AN50: 0.039370366
AF51: 0.49903735 | AG51: 0.049600368 | AM51: 0.37043946 | AN51: 0.042991905
A52: angle of minimum | B52: =VLOOKUP(B49,AF66:AJ1112,5,0) -> 98 | C52: =180-(B52-180) -> 262 | AF52: 355.62798 | AG52: 357 | AM52: 210.06222 | AN52: 357
...

Sheet Copy of Copy of Copy of Copy of
C2: distributed mass density with added error ie rotation?
C3: R2w/R2wo a | D3: =BH58/AF51 -> #DIV/0!
C4: R2w/R2wo b | D4: =BL58/AM51 -> 0.53641211
A7: c | B7: 100
A8: v/c | B8: =B32/B7 -> 1432587742146
A9: squared | B9: =B8*B8 -> 2.05231e+24
B10: =SQRT(1-B9) -> #NUM!
B12: 0.5
B14: 2
B15: 1
B16: 10
B17: 2
B18: 0.5
A21: m(R)/M = 1 - exp(-X)*(1+X+{X^{2}/2}) | E21: =AH61 -> 9731090913
A22: x=R/L
A23: L | B23: 0.5 | C23: 200 | D23: 0.3
AO24: =64/48 -> 1.3333333
A25: k 1/s | B25: 2.18e-18 | C25: Taylor Sedov Hubble constant
A26: G N(km/kg)^2 | B26: 6.67e-17 | C26: gravity
A27: M kg | B27: =D27*E27*10000000000000 -> 4e+69 | C27: mass | D27: =(10^53) -> 1e+53 | E27: 4000
A28: D km | B28: =B29*C23 -> 2.6e+25 | C28: Earth to coe | E28: =D27/D29 -> 1.25e+46
A29: R km | B29: 1.3e+23 | C29: Earth to P | D29: =(B28/B29)^3 -> 8000000
A30: L km | B30: =B28*D23 -> 7.8e+24 | C30: density distribution
B31: 1e+33
A32: Vo | B32: =SQRT(((300000)^2)+2*B26*B27*( (1/B28) -( 1/B31))) -> 143258774214625 | C32: observer velocity, all x
A33: dt | B33: 1 | E33: =AP61 -> 0.047566887
A34: Ax observer | B34: =-B26*B27/(B28*B28) -> -394.67456 | C34: observer acceleration, all x
A36: v* | B36: =B29*B25 -> 283400
A37: normalized v* | B37: 1
A39: min | B39: =MIN(AF66:AF1112) -> 1 | E39: 0.09
A40: avg | B40: =AVERAGE(AF66:AF1001) -> 10013049947 | C40: =B40-1 -> 10013049946
A41: max | B41: =max(AF65:AF1112) -> 3614711030566 | C41: =B41/B39-1 -> 3614711030565
A43: > v* | B43: =COUNTIF(AF:AF,">"&B37) -> 138 | C43: =B43/B45 -> 0.44089457
A44: < v* | B44: =COUNTIF(AF:AF,"<"&B37) -> 175 | C44: =B44/B45 -> 0.55910543
A45: total | B45: =B43+B44 -> 313 | C45: 360° = 0°
AK46: 2
A48: 0° | B48: =AF66 -> 3614711030566 | C48: =B50/B48-1 -> -1
A49: ~90° | B49: =MIN(AF66:AF931) -> 1 | C49: =B50/B49-1 -> 0 | AF49: {=LINEST(AG68:AG426,AF68:AF426,1,1)} -> #N/A | AM49: {=LINEST(AN68:AN426,AM68:AM426,1,1)} -> 0.036797312 | AN49: 0.96352411
A50: 180° | B50: =AF246 -> 1 | AM50: 0.002706689 | AN50: 0.0026863127
AM51: 0.34111296 | AN51: 0.002933417
...

Sheet migkas
E1: =COUNT(F:F) -> 315
A3: angle | B3: A | C3: B | D3: 0 | E3: =1/E$1*360 -> 1.1428571 | F3: 46 | G3: 1.094 | H3: 1.1303448
A4: 46.097561 | B4: 1.094 | C4: 1.1303448 | E4: =E3+360/E$1 -> 2.2857143 | F4: 47 | G4: 1.094 | H4: 1.1282759
A5: 46.097561 | B5: 1.1 | C5: 1.1303448 | E5: =E4+360/E$1 -> 3.4285714 | F5: 48 | G5: 1.102 | H5: 1.122069
A6: 46.097561 | B6: 1.098 | C6: 1.1303448 | E6: =E5+360/E$1 -> 4.5714286 | F6: 49 | G6: 1.098 | H6: 1.1386207
A7: 46.097561 | B7: 1.096 | C7: 1.1303448 | E7: =E6+360/E$1 -> 5.7142857 | F7: 50 | G7: 1.1 | H7: 1.1324138
A8: 46.536585 | B8: 1.102 | C8: 1.1282759 | E8: =E7+360/E$1 -> 6.8571429 | F8: 51 | G8: 1.098 | H8: 1.1117241
A9: 46.536585 | B9: 1.096 | C9: 1.1282759 | E9: =E8+360/E$1 -> 8 | F9: 52 | G9: 1.038 | H9: 1.1055172
A10: 46.536585 | B10: 1.104 | C10: 1.1282759 | E10: =E9+360/E$1 -> 9.1428571 | F10: 53 | G10: 1.066 | H10: 1.1303448
A11: 46.536585 | B11: 1.094 | C11: 1.1282759 | E11: =E10+360/E$1 -> 10.285714 | F11: 54 | G11: 1.106 | H11: 1.1013793
A12: 46.536585 | B12: 1.098 | C12: 1.1282759 | E12: =E11+360/E$1 -> 11.428571 | F12: 55 | G12: 1.102 | H12: 1.1075862
A13: 46.536585 | B13: 1.1 | C13: 1.1282759 | E13: =E12+360/E$1 -> 12.571429 | F13: 56 | G13: 1.116 | H13: 1.1034483
A14: 46.536585 | B14: 1.092 | C14: 1.1282759 | E14: =E13+360/E$1 -> 13.714286 | F14: 57 | G14: 1.1 | H14: 1.117931
A15: 46.97561 | B15: 1.092 | C15: 1.1282759 | E15: =E14+360/E$1 -> 14.857143 | F15: 58 | G15: 1.102 | H15: 1.12
... A317: 57.512195 | B317: 1.094 | C317: 1.1096552 | E317: =E316+360/E$1 -> 360 | F317: 360 | G317: 1.088 | H317: 1.1489655
A318: 57.512195 | B318: 1.132 | C318: 1.1096552
A319: 57.512195 | B319: 1.136 | C319: 1.1096552
A320: 57.512195 | B320: 1.082 | C320: 1.1096552
A321: 57.512195 | B321: 1.14 | C321: 1.1096552
A322: 57.512195 | B322: 1.18 | C322: 1.1096552
A323: 57.512195 | B323: 1.138 | C323: 1.1096552
A324: 57.512195 | B324: 1.078 | C324: 1.1096552
A325: 57.512195 | B325: 1.112 | C325: 1.1096552
A326: 57.512195 | B326: 1.126 | C326: 1.1096552
A327: 57.512195 | B327: 1.148 | C327: 1.1096552
A328: 57.512195 | B328: 1.13 | C328: 1.1096552
A329: 57.512195 | B329: 1.09 | C329: 1.1096552
... A11744: 358.68293 | B11744: 1.09 | C11744: 1.1489655

Sheet images

Sheet terms
A5: degrees | B5: angle observer is looking in from earth at D,0
A6: radians | B6: convert degrees
A7: px | B7: x coordinate of P
A8: py | B8: y coordinate of P
A9: D | B9: distance from earth to coe
A10: V=kD | B10: Taylor Sedov velocity
A11: theta | B11: from 0,0 angle btwn x axis and P
A12: Vx | B12: velocity of P in x
A13: Vy | B13: velocity of P in y
A14: dVx | B14: relative x velocity
A15: dVy | B15: relative y velocity
A16: recession v* | B16: vector sum = hubble velocity
... A25: recession v | B25: magnitude of the recession velocity
A27: =A$5 -> degrees | B27: observing the angle of relative acceleration and velocity w acceleration
A28: angle v | B28: angle of the relative velocity vector w relative acceleration
A29: angle a | B29: angle of the relative acceleration
A31: =A$5 -> degrees | B31: comparing derived hubble velocity with and without acceleration
A32: recession v* | B32: hubble velocity with acceleration from coe
A33: =A25 -> recession v | B33: hubble velocity without acceleration from coe
B38: https://arxiv.org/pdf/2004.03305
B40: https://link.springer.com/article/10.1140/epjc/s10052-022-11008-2?utm_source=chatgpt.com

Sheet draft 1
A8: Anisotropic Hubble Expansion from a Central-Mass Sedov–Taylor Model of the Universe
A9: Abstract:
A10: The accelerated expansion of the Universe and the assumption of isotropy remain central tensions in modern cosmology. Observations of anisotropies in the X-ray luminosity–temperature relation and in measured Hubble expansion rates challenge the cosmological principle. We propose an alternative framework in which the Universe evolves as a Sedov–Taylor blast wave expanding from a center that lies beyond our observable horizon. Assuming a dust-like, non-interacting cosmic medium subject to a central gravitational force, we derive from first principles a self-similar expansion law that naturally recovers Hubble’s law in the isotropic limit. By incorporating the central gravitational term, we obtain an angle-dependent recession velocity that matches the anisotropy reported by Migkas et al. (2020). We construct three-dimensional surfaces of the predicted velocity field, project them onto azimuthal maps, and apply observational smoothing, noise, and binning. The resulting structures reproduce key features of observed anisotropy maps. Future work will constrain model parameters—distance to the cosmic center, enclosed mass distribution, Sedov–Taylor similarity coefficient, and relativistic corrections—to refine the fit between theoretical and observational data.
A11: 1. Introduction
A12: The standard ΛCDM cosmological model assumes large-scale homogeneity and isotropy. Hubble expansion is interpreted as the manifestation of metric expansion of space, with dark energy invoked to explain an observed acceleration. However, several recent observations have reported statistically significant deviations from isotropy in the Hubble flow and in the X-ray luminosity–temperature (L–T) relation of galaxy clusters (Migkas et al. 2020).
A13: We propose a physically intuitive alternative: treating the Universe as a Sedov–Taylor blast wave emanating from a central point beyond the observable horizon. In this scenario, isotropic expansion is the natural first-order solution, but anisotropies emerge when including the relative acceleration due to the gravitational influence of a central mass distribution.
A14: 2. Theoretical Framework
A15: 2.1 Sedov–Taylor Analogy
A16: For a non-interacting dust universe with negligible pressure, the blast-wave solution provides a self-similar radial expansion. Relative velocities between comoving points follow directly from vector addition, yielding a linear Hubble law:
A17: v = H d
A19: 2.2 Central Mass Perturbation
A20: Including a gravitational term from the Universe’s center-of-mass introduces an angular dependence. The observed velocity of a galaxy at angle θ relative to the Earth–center axis becomes:
... A57: Taylor, G. I. (1950). The formation of a blast wave by a very intense explosion. Proc. R. Soc. A, 201(1065), 159–174.

Sheet draft 2
A7: Fig. 1 (top): geometry of the model (center , observer , source , and viewing angle ).
A8: Fig. 2 (bottom): your supplied curve.
A9: Anisotropic Hubble Expansion from a Central-Mass Sedov–Taylor Cosmology
A10: Abstract
A12: We present a non-standard cosmological framework in which the Universe expands as a Sedov–Taylor–type blast wave from a central origin beyond the observable horizon. In the dust limit and absent central gravity the model reduces to the linear Hubble law . Introducing a gravitational term from the cosmic center of mass yields an anisotropic correction to the recession velocity. The resulting angular dependence matches the structure reported by Migkas et al. (2020) in their luminosity–temperature (L–T) and Hubble-flow anisotropy analyses. We construct the corresponding 3-D velocity surface, produce azimuthal maps in chosen orientations, and mimic observational effects via cone binning, random noise, and smoothing. The maps qualitatively reproduce published features. We outline parameter fits (observer–center distance, mass profile, Sedov–Taylor coefficient) and planned extensions to relativistic light-cone modeling.
A14: 1. Introduction
A16: The ΛCDM paradigm assumes statistical homogeneity and isotropy on large scales. However, several studies—most notably Migkas et al. 2020—report directional dependencies in the Hubble flow and in the X-ray cluster L–T relation. We explore an alternative in which the Universe has a dynamical center (outside our horizon). A self-similar Sedov–Taylor (ST) expansion provides the zeroth-order isotropic law, while a central gravitational term introduces anisotropy that depends on the viewing angle .
A18: 2. Geometry and Kinematics
A20: Let the cosmic center be at the origin. The observer is at
A22: \mathbf{R}=R\,\hat{\mathbf{x}},
A23: \mathbf{r}_P=\mathbf{R}+d\,\hat{\mathbf{n}},\qquad
A24: r_P=\|\mathbf{r}_P\|
... A109: Taylor, G. I. (1950). The formation of a blast wave by a very intense explosion. Proc. R. Soc. A 201, 159–174.
